{
    DataVersion: 3955,
    size: [4, 8, 4],
    data: [
        {pos: [0, 0, 0], state: "mekanism:thermal_evaporation_block", nbt: {id: "mekanism:thermal_evaporation_block", inventory_id: [I; 1968034496, -1402714844, -1678774626, -513083046], redstone: 0b}},
        {pos: [0, 0, 1], state: "mekanism:thermal_evaporation_block", nbt: {id: "mekanism:thermal_evaporation_block", inventory_id: [I; 1968034496, -1402714844, -1678774626, -513083046], redstone: 0b}},
        {pos: [0, 0, 2], state: "mekanism:thermal_evaporation_block", nbt: {id: "mekanism:thermal_evaporation_block", inventory_id: [I; 1968034496, -1402714844, -1678774626, -513083046], redstone: 0b}},
        {pos: [0, 0, 3], state: "mekanism:thermal_evaporation_block", nbt: {id: "mekanism:thermal_evaporation_block", inventory_id: [I; 1968034496, -1402714844, -1678774626, -513083046], redstone: 0b}},
        {pos: [1, 0, 0], state: "mekanism:thermal_evaporation_block", nbt: {id: "mekanism:thermal_evaporation_block", inventory_id: [I; 1968034496, -1402714844, -1678774626, -513083046], redstone: 0b}},
        {pos: [1, 0, 1], state: "mekanism:thermal_evaporation_block", nbt: {id: "mekanism:thermal_evaporation_block", inventory_id: [I; 1968034496, -1402714844, -1678774626, -513083046], redstone: 0b}},
        {pos: [1, 0, 2], state: "mekanism:thermal_evaporation_block", nbt: {id: "mekanism:thermal_evaporation_block", inventory_id: [I; 1968034496, -1402714844, -1678774626, -513083046], redstone: 0b}},
        {pos: [1, 0, 3], state: "mekanism:thermal_evaporation_block", nbt: {id: "mekanism:thermal_evaporation_block", inventory_id: [I; 1968034496, -1402714844, -1678774626, -513083046], redstone: 0b}},
        {pos: [2, 0, 0], state: "mekanism:thermal_evaporation_block", nbt: {id: "mekanism:thermal_evaporation_block", inventory_id: [I; 1968034496, -1402714844, -1678774626, -513083046], redstone: 0b}},
        {pos: [2, 0, 1], state: "mekanism:thermal_evaporation_block", nbt: {id: "mekanism:thermal_evaporation_block", inventory_id: [I; 1968034496, -1402714844, -1678774626, -513083046], redstone: 0b}},
        {pos: [2, 0, 2], state: "mekanism:thermal_evaporation_block", nbt: {id: "mekanism:thermal_evaporation_block", inventory_id: [I; 1968034496, -1402714844, -1678774626, -513083046], redstone: 0b}},
        {pos: [2, 0, 3], state: "mekanism:thermal_evaporation_block", nbt: {id: "mekanism:thermal_evaporation_block", inventory_id: [I; 1968034496, -1402714844, -1678774626, -513083046], redstone: 0b}},
        {pos: [3, 0, 0], state: "mekanism:thermal_evaporation_block", nbt: {id: "mekanism:thermal_evaporation_block", inventory_id: [I; 1968034496, -1402714844, -1678774626, -513083046], redstone: 0b}},
        {pos: [3, 0, 1], state: "mekanism:thermal_evaporation_block", nbt: {id: "mekanism:thermal_evaporation_block", inventory_id: [I; 1968034496, -1402714844, -1678774626, -513083046], redstone: 0b}},
        {pos: [3, 0, 2], state: "mekanism:thermal_evaporation_block", nbt: {id: "mekanism:thermal_evaporation_block", inventory_id: [I; 1968034496, -1402714844, -1678774626, -513083046], redstone: 0b}},
        {pos: [3, 0, 3], state: "mekanism:thermal_evaporation_block", nbt: {id: "mekanism:thermal_evaporation_block", inventory_id: [I; 1968034496, -1402714844, -1678774626, -513083046], redstone: 0b}},
        {pos: [0, 1, 0], state: "mekanism:thermal_evaporation_block", nbt: {id: "mekanism:thermal_evaporation_block", inventory_id: [I; 1968034496, -1402714844, -1678774626, -513083046], redstone: 0b}},
        {pos: [0, 1, 1], state: "mekanism:structural_glass", nbt: {id: "mekanism:structural_glass", redstone: 0b}},
        {pos: [0, 1, 2], state: "mekanism:structural_glass", nbt: {id: "mekanism:structural_glass", redstone: 0b}},
        {pos: [0, 1, 3], state: "mekanism:thermal_evaporation_block", nbt: {id: "mekanism:thermal_evaporation_block", inventory_id: [I; 1968034496, -1402714844, -1678774626, -513083046], redstone: 0b}},
        {pos: [1, 1, 0], state: "mekanism:thermal_evaporation_controller{active:true,facing:north}", nbt: {active_state: 1b, id: "mekanism:thermal_evaporation_controller", inventory_id: [I; 1968034496, -1402714844, -1678774626, -513083046], redstone: 0b, update_delay: 0}},
        {pos: [1, 1, 3], state: "mekanism:structural_glass", nbt: {id: "mekanism:structural_glass", redstone: 0b}},
        {pos: [2, 1, 0], state: "mekanism:structural_glass", nbt: {id: "mekanism:structural_glass", redstone: 0b}},
        {pos: [2, 1, 3], state: "mekanism:structural_glass", nbt: {id: "mekanism:structural_glass", redstone: 0b}},
        {pos: [3, 1, 0], state: "mekanism:thermal_evaporation_block", nbt: {id: "mekanism:thermal_evaporation_block", inventory_id: [I; 1968034496, -1402714844, -1678774626, -513083046], redstone: 0b}},
        {pos: [3, 1, 1], state: "mekanism:thermal_evaporation_valve", nbt: {current_redstone: 0, id: "mekanism:thermal_evaporation_valve", inventory_id: [I; 1968034496, -1402714844, -1678774626, -513083046], redstone: 0b}},
        {pos: [3, 1, 2], state: "mekanism:thermal_evaporation_valve", nbt: {current_redstone: 0, id: "mekanism:thermal_evaporation_valve", inventory_id: [I; 1968034496, -1402714844, -1678774626, -513083046], redstone: 0b}},
        {pos: [3, 1, 3], state: "mekanism:thermal_evaporation_block", nbt: {id: "mekanism:thermal_evaporation_block", inventory_id: [I; 1968034496, -1402714844, -1678774626, -513083046], redstone: 0b}},
        {pos: [0, 2, 0], state: "mekanism:thermal_evaporation_block", nbt: {id: "mekanism:thermal_evaporation_block", inventory_id: [I; 1968034496, -1402714844, -1678774626, -513083046], redstone: 0b}},
        {pos: [0, 2, 1], state: "mekanism:structural_glass", nbt: {id: "mekanism:structural_glass", redstone: 0b}},
        {pos: [0, 2, 2], state: "mekanism:structural_glass", nbt: {id: "mekanism:structural_glass", redstone: 0b}},
        {pos: [0, 2, 3], state: "mekanism:thermal_evaporation_block", nbt: {id: "mekanism:thermal_evaporation_block", inventory_id: [I; 1968034496, -1402714844, -1678774626, -513083046], redstone: 0b}},
        {pos: [1, 2, 0], state: "mekanism:structural_glass", nbt: {id: "mekanism:structural_glass", redstone: 0b}},
        {pos: [1, 2, 3], state: "mekanism:structural_glass", nbt: {id: "mekanism:structural_glass", redstone: 0b}},
        {pos: [2, 2, 0], state: "mekanism:structural_glass", nbt: {id: "mekanism:structural_glass", redstone: 0b}},
        {pos: [2, 2, 3], state: "mekanism:structural_glass", nbt: {id: "mekanism:structural_glass", redstone: 0b}},
        {pos: [3, 2, 0], state: "mekanism:thermal_evaporation_block", nbt: {id: "mekanism:thermal_evaporation_block", inventory_id: [I; 1968034496, -1402714844, -1678774626, -513083046], redstone: 0b}},
        {pos: [3, 2, 1], state: "mekanism:structural_glass", nbt: {id: "mekanism:structural_glass", redstone: 0b}},
        {pos: [3, 2, 2], state: "mekanism:structural_glass", nbt: {id: "mekanism:structural_glass", redstone: 0b}},
        {pos: [3, 2, 3], state: "mekanism:thermal_evaporation_block", nbt: {id: "mekanism:thermal_evaporation_block", inventory_id: [I; 1968034496, -1402714844, -1678774626, -513083046], redstone: 0b}},
        {pos: [0, 3, 0], state: "mekanism:thermal_evaporation_block", nbt: {id: "mekanism:thermal_evaporation_block", inventory_id: [I; 1968034496, -1402714844, -1678774626, -513083046], redstone: 0b}},
        {pos: [0, 3, 1], state: "mekanism:structural_glass", nbt: {id: "mekanism:structural_glass", redstone: 0b}},
        {pos: [0, 3, 2], state: "mekanism:structural_glass", nbt: {id: "mekanism:structural_glass", redstone: 0b}},
        {pos: [0, 3, 3], state: "mekanism:thermal_evaporation_block", nbt: {id: "mekanism:thermal_evaporation_block", inventory_id: [I; 1968034496, -1402714844, -1678774626, -513083046], redstone: 0b}},
        {pos: [1, 3, 0], state: "mekanism:structural_glass", nbt: {id: "mekanism:structural_glass", redstone: 0b}},
        {pos: [1, 3, 3], state: "mekanism:structural_glass", nbt: {id: "mekanism:structural_glass", redstone: 0b}},
        {pos: [2, 3, 0], state: "mekanism:structural_glass", nbt: {id: "mekanism:structural_glass", redstone: 0b}},
        {pos: [2, 3, 3], state: "mekanism:structural_glass", nbt: {id: "mekanism:structural_glass", redstone: 0b}},
        {pos: [3, 3, 0], state: "mekanism:thermal_evaporation_block", nbt: {id: "mekanism:thermal_evaporation_block", inventory_id: [I; 1968034496, -1402714844, -1678774626, -513083046], redstone: 0b}},
        {pos: [3, 3, 1], state: "mekanism:structural_glass", nbt: {id: "mekanism:structural_glass", redstone: 0b}},
        {pos: [3, 3, 2], state: "mekanism:structural_glass", nbt: {id: "mekanism:structural_glass", redstone: 0b}},
        {pos: [3, 3, 3], state: "mekanism:thermal_evaporation_block", nbt: {id: "mekanism:thermal_evaporation_block", inventory_id: [I; 1968034496, -1402714844, -1678774626, -513083046], redstone: 0b}},
        {pos: [0, 4, 0], state: "mekanism:thermal_evaporation_block", nbt: {id: "mekanism:thermal_evaporation_block", inventory_id: [I; 1968034496, -1402714844, -1678774626, -513083046], redstone: 0b}},
        {pos: [0, 4, 1], state: "mekanism:structural_glass", nbt: {id: "mekanism:structural_glass", redstone: 0b}},
        {pos: [0, 4, 2], state: "mekanism:structural_glass", nbt: {id: "mekanism:structural_glass", redstone: 0b}},
        {pos: [0, 4, 3], state: "mekanism:thermal_evaporation_block", nbt: {id: "mekanism:thermal_evaporation_block", inventory_id: [I; 1968034496, -1402714844, -1678774626, -513083046], redstone: 0b}},
        {pos: [1, 4, 0], state: "mekanism:structural_glass", nbt: {id: "mekanism:structural_glass", redstone: 0b}},
        {pos: [1, 4, 3], state: "mekanism:structural_glass", nbt: {id: "mekanism:structural_glass", redstone: 0b}},
        {pos: [2, 4, 0], state: "mekanism:structural_glass", nbt: {id: "mekanism:structural_glass", redstone: 0b}},
        {pos: [2, 4, 3], state: "mekanism:structural_glass", nbt: {id: "mekanism:structural_glass", redstone: 0b}},
        {pos: [3, 4, 0], state: "mekanism:thermal_evaporation_block", nbt: {id: "mekanism:thermal_evaporation_block", inventory_id: [I; 1968034496, -1402714844, -1678774626, -513083046], redstone: 0b}},
        {pos: [3, 4, 1], state: "mekanism:structural_glass", nbt: {id: "mekanism:structural_glass", redstone: 0b}},
        {pos: [3, 4, 2], state: "mekanism:structural_glass", nbt: {id: "mekanism:structural_glass", redstone: 0b}},
        {pos: [3, 4, 3], state: "mekanism:thermal_evaporation_block", nbt: {id: "mekanism:thermal_evaporation_block", inventory_id: [I; 1968034496, -1402714844, -1678774626, -513083046], redstone: 0b}},
        {pos: [0, 5, 0], state: "mekanism:thermal_evaporation_block", nbt: {id: "mekanism:thermal_evaporation_block", inventory_id: [I; 1968034496, -1402714844, -1678774626, -513083046], redstone: 0b}},
        {pos: [0, 5, 1], state: "mekanism:structural_glass", nbt: {id: "mekanism:structural_glass", redstone: 0b}},
        {pos: [0, 5, 2], state: "mekanism:structural_glass", nbt: {id: "mekanism:structural_glass", redstone: 0b}},
        {pos: [0, 5, 3], state: "mekanism:thermal_evaporation_block", nbt: {id: "mekanism:thermal_evaporation_block", inventory_id: [I; 1968034496, -1402714844, -1678774626, -513083046], redstone: 0b}},
        {pos: [1, 5, 0], state: "mekanism:structural_glass", nbt: {id: "mekanism:structural_glass", redstone: 0b}},
        {pos: [1, 5, 3], state: "mekanism:structural_glass", nbt: {id: "mekanism:structural_glass", redstone: 0b}},
        {pos: [2, 5, 0], state: "mekanism:structural_glass", nbt: {id: "mekanism:structural_glass", redstone: 0b}},
        {pos: [2, 5, 3], state: "mekanism:structural_glass", nbt: {id: "mekanism:structural_glass", redstone: 0b}},
        {pos: [3, 5, 0], state: "mekanism:thermal_evaporation_block", nbt: {id: "mekanism:thermal_evaporation_block", inventory_id: [I; 1968034496, -1402714844, -1678774626, -513083046], redstone: 0b}},
        {pos: [3, 5, 1], state: "mekanism:structural_glass", nbt: {id: "mekanism:structural_glass", redstone: 0b}},
        {pos: [3, 5, 2], state: "mekanism:structural_glass", nbt: {id: "mekanism:structural_glass", redstone: 0b}},
        {pos: [3, 5, 3], state: "mekanism:thermal_evaporation_block", nbt: {id: "mekanism:thermal_evaporation_block", inventory_id: [I; 1968034496, -1402714844, -1678774626, -513083046], redstone: 0b}},
        {pos: [0, 6, 0], state: "mekanism:thermal_evaporation_block", nbt: {id: "mekanism:thermal_evaporation_block", inventory_id: [I; 1968034496, -1402714844, -1678774626, -513083046], redstone: 0b}},
        {pos: [0, 6, 1], state: "mekanism:structural_glass", nbt: {id: "mekanism:structural_glass", redstone: 0b}},
        {pos: [0, 6, 2], state: "mekanism:structural_glass", nbt: {id: "mekanism:structural_glass", redstone: 0b}},
        {pos: [0, 6, 3], state: "mekanism:thermal_evaporation_block", nbt: {id: "mekanism:thermal_evaporation_block", inventory_id: [I; 1968034496, -1402714844, -1678774626, -513083046], redstone: 0b}},
        {pos: [1, 6, 0], state: "mekanism:structural_glass", nbt: {id: "mekanism:structural_glass", redstone: 0b}},
        {pos: [1, 6, 3], state: "mekanism:structural_glass", nbt: {id: "mekanism:structural_glass", redstone: 0b}},
        {pos: [2, 6, 0], state: "mekanism:structural_glass", nbt: {id: "mekanism:structural_glass", redstone: 0b}},
        {pos: [2, 6, 3], state: "mekanism:structural_glass", nbt: {id: "mekanism:structural_glass", redstone: 0b}},
        {pos: [3, 6, 0], state: "mekanism:thermal_evaporation_block", nbt: {id: "mekanism:thermal_evaporation_block", inventory_id: [I; 1968034496, -1402714844, -1678774626, -513083046], redstone: 0b}},
        {pos: [3, 6, 1], state: "mekanism:structural_glass", nbt: {id: "mekanism:structural_glass", redstone: 0b}},
        {pos: [3, 6, 2], state: "mekanism:structural_glass", nbt: {id: "mekanism:structural_glass", redstone: 0b}},
        {pos: [3, 6, 3], state: "mekanism:thermal_evaporation_block", nbt: {id: "mekanism:thermal_evaporation_block", inventory_id: [I; 1968034496, -1402714844, -1678774626, -513083046], redstone: 0b}},
        {pos: [0, 7, 0], state: "mekanism:thermal_evaporation_block", nbt: {id: "mekanism:thermal_evaporation_block", inventory_id: [I; 1968034496, -1402714844, -1678774626, -513083046], redstone: 0b}},
        {pos: [0, 7, 1], state: "mekanism:thermal_evaporation_block", nbt: {id: "mekanism:thermal_evaporation_block", inventory_id: [I; 1968034496, -1402714844, -1678774626, -513083046], redstone: 0b}},
        {pos: [0, 7, 2], state: "mekanism:thermal_evaporation_block", nbt: {id: "mekanism:thermal_evaporation_block", inventory_id: [I; 1968034496, -1402714844, -1678774626, -513083046], redstone: 0b}},
        {pos: [0, 7, 3], state: "mekanism:thermal_evaporation_block", nbt: {id: "mekanism:thermal_evaporation_block", inventory_id: [I; 1968034496, -1402714844, -1678774626, -513083046], redstone: 0b}},
        {pos: [1, 7, 0], state: "mekanism:thermal_evaporation_block", nbt: {id: "mekanism:thermal_evaporation_block", inventory_id: [I; 1968034496, -1402714844, -1678774626, -513083046], redstone: 0b}},
        {pos: [1, 7, 3], state: "mekanism:thermal_evaporation_block", nbt: {id: "mekanism:thermal_evaporation_block", inventory_id: [I; 1968034496, -1402714844, -1678774626, -513083046], redstone: 0b}},
        {pos: [2, 7, 0], state: "mekanism:thermal_evaporation_block", nbt: {id: "mekanism:thermal_evaporation_block", inventory_id: [I; 1968034496, -1402714844, -1678774626, -513083046], redstone: 0b}},
        {pos: [2, 7, 3], state: "mekanism:thermal_evaporation_block", nbt: {id: "mekanism:thermal_evaporation_block", inventory_id: [I; 1968034496, -1402714844, -1678774626, -513083046], redstone: 0b}},
        {pos: [3, 7, 0], state: "mekanism:thermal_evaporation_block", nbt: {id: "mekanism:thermal_evaporation_block", inventory_id: [I; 1968034496, -1402714844, -1678774626, -513083046], redstone: 0b}},
        {pos: [3, 7, 1], state: "mekanism:thermal_evaporation_block", nbt: {id: "mekanism:thermal_evaporation_block", inventory_id: [I; 1968034496, -1402714844, -1678774626, -513083046], redstone: 0b}},
        {pos: [3, 7, 2], state: "mekanism:thermal_evaporation_block", nbt: {id: "mekanism:thermal_evaporation_block", inventory_id: [I; 1968034496, -1402714844, -1678774626, -513083046], redstone: 0b}},
        {pos: [3, 7, 3], state: "mekanism:thermal_evaporation_block", nbt: {id: "mekanism:thermal_evaporation_block", inventory_id: [I; 1968034496, -1402714844, -1678774626, -513083046], redstone: 0b}}
    ],
    entities: [],
    palette: [
        "mekanism:thermal_evaporation_block",
        "mekanism:structural_glass",
        "mekanism:thermal_evaporation_controller{active:true,facing:north}",
        "mekanism:thermal_evaporation_valve"
    ]
}