{
    DataVersion: 3955,
    size: [4, 4, 4],
    data: [
        {pos: [0, 0, 0], state: "mekanism:induction_casing", nbt: {current_redstone: 0, id: "mekanism:induction_casing", inventory_id: [I; 1661664914, -527545051, -1646468272, 1937833533], redstone: 0b}},
        {pos: [0, 0, 1], state: "mekanism:induction_casing", nbt: {current_redstone: 0, id: "mekanism:induction_casing", inventory_id: [I; 1661664914, -527545051, -1646468272, 1937833533], redstone: 0b}},
        {pos: [0, 0, 2], state: "mekanism:induction_casing", nbt: {current_redstone: 0, id: "mekanism:induction_casing", inventory_id: [I; 1661664914, -527545051, -1646468272, 1937833533], redstone: 0b}},
        {pos: [0, 0, 3], state: "mekanism:induction_casing", nbt: {current_redstone: 0, id: "mekanism:induction_casing", inventory_id: [I; 1661664914, -527545051, -1646468272, 1937833533], redstone: 0b}},
        {pos: [1, 0, 0], state: "mekanism:induction_casing", nbt: {current_redstone: 0, id: "mekanism:induction_casing", inventory_id: [I; 1661664914, -527545051, -1646468272, 1937833533], redstone: 0b}},
        {pos: [1, 0, 1], state: "mekanism:structural_glass", nbt: {id: "mekanism:structural_glass", redstone: 0b}},
        {pos: [1, 0, 2], state: "mekanism:structural_glass", nbt: {id: "mekanism:structural_glass", redstone: 0b}},
        {pos: [1, 0, 3], state: "mekanism:induction_casing", nbt: {current_redstone: 0, id: "mekanism:induction_casing", inventory_id: [I; 1661664914, -527545051, -1646468272, 1937833533], redstone: 0b}},
        {pos: [2, 0, 0], state: "mekanism:induction_casing", nbt: {current_redstone: 0, id: "mekanism:induction_casing", inventory_id: [I; 1661664914, -527545051, -1646468272, 1937833533], redstone: 0b}},
        {pos: [2, 0, 1], state: "mekanism:structural_glass", nbt: {id: "mekanism:structural_glass", redstone: 0b}},
        {pos: [2, 0, 2], state: "mekanism:structural_glass", nbt: {id: "mekanism:structural_glass", redstone: 0b}},
        {pos: [2, 0, 3], state: "mekanism:induction_casing", nbt: {current_redstone: 0, id: "mekanism:induction_casing", inventory_id: [I; 1661664914, -527545051, -1646468272, 1937833533], redstone: 0b}},
        {pos: [3, 0, 0], state: "mekanism:induction_casing", nbt: {current_redstone: 0, id: "mekanism:induction_casing", inventory_id: [I; 1661664914, -527545051, -1646468272, 1937833533], redstone: 0b}},
        {pos: [3, 0, 1], state: "mekanism:induction_casing", nbt: {current_redstone: 0, id: "mekanism:induction_casing", inventory_id: [I; 1661664914, -527545051, -1646468272, 1937833533], redstone: 0b}},
        {pos: [3, 0, 2], state: "mekanism:induction_casing", nbt: {current_redstone: 0, id: "mekanism:induction_casing", inventory_id: [I; 1661664914, -527545051, -1646468272, 1937833533], redstone: 0b}},
        {pos: [3, 0, 3], state: "mekanism:induction_casing", nbt: {current_redstone: 0, id: "mekanism:induction_casing", inventory_id: [I; 1661664914, -527545051, -1646468272, 1937833533], redstone: 0b}},
        {pos: [0, 1, 0], state: "mekanism:induction_casing", nbt: {current_redstone: 0, id: "mekanism:induction_casing", inventory_id: [I; 1661664914, -527545051, -1646468272, 1937833533], redstone: 0b}},
        {pos: [0, 1, 1], state: "mekanism:structural_glass", nbt: {id: "mekanism:structural_glass", redstone: 0b}},
        {pos: [0, 1, 2], state: "mekanism:structural_glass", nbt: {id: "mekanism:structural_glass", redstone: 0b}},
        {pos: [0, 1, 3], state: "mekanism:induction_casing", nbt: {current_redstone: 0, id: "mekanism:induction_casing", inventory_id: [I; 1661664914, -527545051, -1646468272, 1937833533], redstone: 0b}},
        {pos: [1, 1, 0], state: "mekanism:structural_glass", nbt: {id: "mekanism:structural_glass", redstone: 0b}},
        {pos: [1, 1, 1], state: "mekanism:basic_induction_cell", nbt: {id: "mekanism:basic_induction_cell", redstone: 0b}},
        {pos: [1, 1, 2], state: "mekanism:basic_induction_cell", nbt: {id: "mekanism:basic_induction_cell", redstone: 0b}},
        {pos: [1, 1, 3], state: "mekanism:induction_port{active:false}", nbt: {active_state: 0b, current_redstone: 0, id: "mekanism:induction_port", inventory_id: [I; 1661664914, -527545051, -1646468272, 1937833533], redstone: 0b, update_delay: 0}},
        {pos: [2, 1, 0], state: "mekanism:structural_glass", nbt: {id: "mekanism:structural_glass", redstone: 0b}},
        {pos: [2, 1, 1], state: "mekanism:basic_induction_cell", nbt: {id: "mekanism:basic_induction_cell", redstone: 0b}},
        {pos: [2, 1, 2], state: "mekanism:basic_induction_cell", nbt: {id: "mekanism:basic_induction_cell", redstone: 0b}},
        {pos: [2, 1, 3], state: "mekanism:structural_glass", nbt: {id: "mekanism:structural_glass", redstone: 0b}},
        {pos: [3, 1, 0], state: "mekanism:induction_casing", nbt: {current_redstone: 0, id: "mekanism:induction_casing", inventory_id: [I; 1661664914, -527545051, -1646468272, 1937833533], redstone: 0b}},
        {pos: [3, 1, 1], state: "mekanism:structural_glass", nbt: {id: "mekanism:structural_glass", redstone: 0b}},
        {pos: [3, 1, 2], state: "mekanism:structural_glass", nbt: {id: "mekanism:structural_glass", redstone: 0b}},
        {pos: [3, 1, 3], state: "mekanism:induction_casing", nbt: {current_redstone: 0, id: "mekanism:induction_casing", inventory_id: [I; 1661664914, -527545051, -1646468272, 1937833533], redstone: 0b}},
        {pos: [0, 2, 0], state: "mekanism:induction_casing", nbt: {current_redstone: 0, id: "mekanism:induction_casing", inventory_id: [I; 1661664914, -527545051, -1646468272, 1937833533], redstone: 0b}},
        {pos: [0, 2, 1], state: "mekanism:structural_glass", nbt: {id: "mekanism:structural_glass", redstone: 0b}},
        {pos: [0, 2, 2], state: "mekanism:structural_glass", nbt: {id: "mekanism:structural_glass", redstone: 0b}},
        {pos: [0, 2, 3], state: "mekanism:induction_casing", nbt: {current_redstone: 0, id: "mekanism:induction_casing", inventory_id: [I; 1661664914, -527545051, -1646468272, 1937833533], redstone: 0b}},
        {pos: [1, 2, 0], state: "mekanism:structural_glass", nbt: {id: "mekanism:structural_glass", redstone: 0b}},
        {pos: [1, 2, 1], state: "mekanism:basic_induction_provider", nbt: {id: "mekanism:basic_induction_provider", redstone: 0b}},
        {pos: [1, 2, 2], state: "mekanism:basic_induction_provider", nbt: {id: "mekanism:basic_induction_provider", redstone: 0b}},
        {pos: [1, 2, 3], state: "mekanism:structural_glass", nbt: {id: "mekanism:structural_glass", redstone: 0b}},
        {pos: [2, 2, 0], state: "mekanism:structural_glass", nbt: {id: "mekanism:structural_glass", redstone: 0b}},
        {pos: [2, 2, 1], state: "mekanism:basic_induction_provider", nbt: {id: "mekanism:basic_induction_provider", redstone: 0b}},
        {pos: [2, 2, 2], state: "mekanism:basic_induction_provider", nbt: {id: "mekanism:basic_induction_provider", redstone: 0b}},
        {pos: [2, 2, 3], state: "mekanism:structural_glass", nbt: {id: "mekanism:structural_glass", redstone: 0b}},
        {pos: [3, 2, 0], state: "mekanism:induction_casing", nbt: {current_redstone: 0, id: "mekanism:induction_casing", inventory_id: [I; 1661664914, -527545051, -1646468272, 1937833533], redstone: 0b}},
        {pos: [3, 2, 1], state: "mekanism:structural_glass", nbt: {id: "mekanism:structural_glass", redstone: 0b}},
        {pos: [3, 2, 2], state: "mekanism:structural_glass", nbt: {id: "mekanism:structural_glass", redstone: 0b}},
        {pos: [3, 2, 3], state: "mekanism:induction_casing", nbt: {current_redstone: 0, id: "mekanism:induction_casing", inventory_id: [I; 1661664914, -527545051, -1646468272, 1937833533], redstone: 0b}},
        {pos: [0, 3, 0], state: "mekanism:induction_casing", nbt: {current_redstone: 0, id: "mekanism:induction_casing", inventory_id: [I; 1661664914, -527545051, -1646468272, 1937833533], redstone: 0b}},
        {pos: [0, 3, 1], state: "mekanism:induction_casing", nbt: {current_redstone: 0, id: "mekanism:induction_casing", inventory_id: [I; 1661664914, -527545051, -1646468272, 1937833533], redstone: 0b}},
        {pos: [0, 3, 2], state: "mekanism:induction_casing", nbt: {current_redstone: 0, id: "mekanism:induction_casing", inventory_id: [I; 1661664914, -527545051, -1646468272, 1937833533], redstone: 0b}},
        {pos: [0, 3, 3], state: "mekanism:induction_casing", nbt: {current_redstone: 0, id: "mekanism:induction_casing", inventory_id: [I; 1661664914, -527545051, -1646468272, 1937833533], redstone: 0b}},
        {pos: [1, 3, 0], state: "mekanism:induction_casing", nbt: {current_redstone: 0, id: "mekanism:induction_casing", inventory_id: [I; 1661664914, -527545051, -1646468272, 1937833533], redstone: 0b}},
        {pos: [1, 3, 1], state: "mekanism:structural_glass", nbt: {id: "mekanism:structural_glass", redstone: 0b}},
        {pos: [1, 3, 2], state: "mekanism:structural_glass", nbt: {id: "mekanism:structural_glass", redstone: 0b}},
        {pos: [1, 3, 3], state: "mekanism:induction_casing", nbt: {current_redstone: 0, id: "mekanism:induction_casing", inventory_id: [I; 1661664914, -527545051, -1646468272, 1937833533], redstone: 0b}},
        {pos: [2, 3, 0], state: "mekanism:induction_casing", nbt: {current_redstone: 0, id: "mekanism:induction_casing", inventory_id: [I; 1661664914, -527545051, -1646468272, 1937833533], redstone: 0b}},
        {pos: [2, 3, 1], state: "mekanism:structural_glass", nbt: {id: "mekanism:structural_glass", redstone: 0b}},
        {pos: [2, 3, 2], state: "mekanism:structural_glass", nbt: {id: "mekanism:structural_glass", redstone: 0b}},
        {pos: [2, 3, 3], state: "mekanism:induction_casing", nbt: {current_redstone: 0, id: "mekanism:induction_casing", inventory_id: [I; 1661664914, -527545051, -1646468272, 1937833533], redstone: 0b}},
        {pos: [3, 3, 0], state: "mekanism:induction_casing", nbt: {current_redstone: 0, id: "mekanism:induction_casing", inventory_id: [I; 1661664914, -527545051, -1646468272, 1937833533], redstone: 0b}},
        {pos: [3, 3, 1], state: "mekanism:induction_casing", nbt: {current_redstone: 0, id: "mekanism:induction_casing", inventory_id: [I; 1661664914, -527545051, -1646468272, 1937833533], redstone: 0b}},
        {pos: [3, 3, 2], state: "mekanism:induction_casing", nbt: {current_redstone: 0, id: "mekanism:induction_casing", inventory_id: [I; 1661664914, -527545051, -1646468272, 1937833533], redstone: 0b}},
        {pos: [3, 3, 3], state: "mekanism:induction_casing", nbt: {current_redstone: 0, id: "mekanism:induction_casing", inventory_id: [I; 1661664914, -527545051, -1646468272, 1937833533], redstone: 0b}}
    ],
    entities: [],
    palette: [
        "mekanism:induction_casing",
        "mekanism:structural_glass",
        "mekanism:basic_induction_cell",
        "mekanism:induction_port{active:false}",
        "mekanism:basic_induction_provider"
    ]
}