{
    DataVersion: 3955,
    size: [5, 5, 5],
    data: [
        {pos: [0, 0, 2], state: "mekanismgenerators:fusion_reactor_frame", nbt: {id: "mekanismgenerators:fusion_reactor_frame", inventory_id: [I; -838099177, -1562622799, -1910657750, 1061773453], redstone: 0b}},
        {pos: [1, 0, 1], state: "mekanismgenerators:fusion_reactor_frame", nbt: {id: "mekanismgenerators:fusion_reactor_frame", inventory_id: [I; -838099177, -1562622799, -1910657750, 1061773453], redstone: 0b}},
        {pos: [1, 0, 2], state: "mekanismgenerators:fusion_reactor_frame", nbt: {id: "mekanismgenerators:fusion_reactor_frame", inventory_id: [I; -838099177, -1562622799, -1910657750, 1061773453], redstone: 0b}},
        {pos: [1, 0, 3], state: "mekanismgenerators:fusion_reactor_frame", nbt: {id: "mekanismgenerators:fusion_reactor_frame", inventory_id: [I; -838099177, -1562622799, -1910657750, 1061773453], redstone: 0b}},
        {pos: [2, 0, 0], state: "mekanismgenerators:fusion_reactor_frame", nbt: {id: "mekanismgenerators:fusion_reactor_frame", inventory_id: [I; -838099177, -1562622799, -1910657750, 1061773453], redstone: 0b}},
        {pos: [2, 0, 1], state: "mekanismgenerators:fusion_reactor_frame", nbt: {id: "mekanismgenerators:fusion_reactor_frame", inventory_id: [I; -838099177, -1562622799, -1910657750, 1061773453], redstone: 0b}},
        {pos: [2, 0, 2], state: "mekanismgenerators:fusion_reactor_frame", nbt: {id: "mekanismgenerators:fusion_reactor_frame", inventory_id: [I; -838099177, -1562622799, -1910657750, 1061773453], redstone: 0b}},
        {pos: [2, 0, 3], state: "mekanismgenerators:fusion_reactor_frame", nbt: {id: "mekanismgenerators:fusion_reactor_frame", inventory_id: [I; -838099177, -1562622799, -1910657750, 1061773453], redstone: 0b}},
        {pos: [2, 0, 4], state: "mekanismgenerators:fusion_reactor_frame", nbt: {id: "mekanismgenerators:fusion_reactor_frame", inventory_id: [I; -838099177, -1562622799, -1910657750, 1061773453], redstone: 0b}},
        {pos: [3, 0, 1], state: "mekanismgenerators:fusion_reactor_frame", nbt: {id: "mekanismgenerators:fusion_reactor_frame", inventory_id: [I; -838099177, -1562622799, -1910657750, 1061773453], redstone: 0b}},
        {pos: [3, 0, 2], state: "mekanismgenerators:fusion_reactor_frame", nbt: {id: "mekanismgenerators:fusion_reactor_frame", inventory_id: [I; -838099177, -1562622799, -1910657750, 1061773453], redstone: 0b}},
        {pos: [3, 0, 3], state: "mekanismgenerators:fusion_reactor_frame", nbt: {id: "mekanismgenerators:fusion_reactor_frame", inventory_id: [I; -838099177, -1562622799, -1910657750, 1061773453], redstone: 0b}},
        {pos: [4, 0, 2], state: "mekanismgenerators:fusion_reactor_frame", nbt: {id: "mekanismgenerators:fusion_reactor_frame", inventory_id: [I; -838099177, -1562622799, -1910657750, 1061773453], redstone: 0b}},
        {pos: [0, 1, 1], state: "mekanismgenerators:fusion_reactor_frame", nbt: {id: "mekanismgenerators:fusion_reactor_frame", inventory_id: [I; -838099177, -1562622799, -1910657750, 1061773453], redstone: 0b}},
        {pos: [0, 1, 2], state: "mekanismgenerators:reactor_glass", nbt: {id: "mekanismgenerators:reactor_glass", redstone: 0b}},
        {pos: [0, 1, 3], state: "mekanismgenerators:fusion_reactor_frame", nbt: {id: "mekanismgenerators:fusion_reactor_frame", inventory_id: [I; -838099177, -1562622799, -1910657750, 1061773453], redstone: 0b}},
        {pos: [1, 1, 0], state: "mekanismgenerators:fusion_reactor_frame", nbt: {id: "mekanismgenerators:fusion_reactor_frame", inventory_id: [I; -838099177, -1562622799, -1910657750, 1061773453], redstone: 0b}},
        {pos: [1, 1, 4], state: "mekanismgenerators:fusion_reactor_frame", nbt: {id: "mekanismgenerators:fusion_reactor_frame", inventory_id: [I; -838099177, -1562622799, -1910657750, 1061773453], redstone: 0b}},
        {pos: [2, 1, 0], state: "mekanismgenerators:reactor_glass", nbt: {id: "mekanismgenerators:reactor_glass", redstone: 0b}},
        {pos: [2, 1, 4], state: "mekanismgenerators:reactor_glass", nbt: {id: "mekanismgenerators:reactor_glass", redstone: 0b}},
        {pos: [3, 1, 0], state: "mekanismgenerators:fusion_reactor_frame", nbt: {id: "mekanismgenerators:fusion_reactor_frame", inventory_id: [I; -838099177, -1562622799, -1910657750, 1061773453], redstone: 0b}},
        {pos: [3, 1, 4], state: "mekanismgenerators:fusion_reactor_frame", nbt: {id: "mekanismgenerators:fusion_reactor_frame", inventory_id: [I; -838099177, -1562622799, -1910657750, 1061773453], redstone: 0b}},
        {pos: [4, 1, 1], state: "mekanismgenerators:fusion_reactor_frame", nbt: {id: "mekanismgenerators:fusion_reactor_frame", inventory_id: [I; -838099177, -1562622799, -1910657750, 1061773453], redstone: 0b}},
        {pos: [4, 1, 2], state: "mekanismgenerators:fusion_reactor_port{active:false}", nbt: {active_state: 0b, id: "mekanismgenerators:fusion_reactor_port", inventory_id: [I; -838099177, -1562622799, -1910657750, 1061773453], redstone: 0b, update_delay: 0}},
        {pos: [4, 1, 3], state: "mekanismgenerators:fusion_reactor_frame", nbt: {id: "mekanismgenerators:fusion_reactor_frame", inventory_id: [I; -838099177, -1562622799, -1910657750, 1061773453], redstone: 0b}},
        {pos: [0, 2, 0], state: "mekanismgenerators:fusion_reactor_frame", nbt: {id: "mekanismgenerators:fusion_reactor_frame", inventory_id: [I; -838099177, -1562622799, -1910657750, 1061773453], redstone: 0b}},
        {pos: [0, 2, 1], state: "mekanismgenerators:reactor_glass", nbt: {id: "mekanismgenerators:reactor_glass", redstone: 0b}},
        {pos: [0, 2, 2], state: "mekanismgenerators:reactor_glass", nbt: {id: "mekanismgenerators:reactor_glass", redstone: 0b}},
        {pos: [0, 2, 3], state: "mekanismgenerators:reactor_glass", nbt: {id: "mekanismgenerators:reactor_glass", redstone: 0b}},
        {pos: [0, 2, 4], state: "mekanismgenerators:fusion_reactor_frame", nbt: {id: "mekanismgenerators:fusion_reactor_frame", inventory_id: [I; -838099177, -1562622799, -1910657750, 1061773453], redstone: 0b}},
        {pos: [1, 2, 0], state: "mekanismgenerators:reactor_glass", nbt: {id: "mekanismgenerators:reactor_glass", redstone: 0b}},
        {pos: [1, 2, 4], state: "mekanismgenerators:reactor_glass", nbt: {id: "mekanismgenerators:reactor_glass", redstone: 0b}},
        {pos: [2, 2, 0], state: "mekanismgenerators:reactor_glass", nbt: {id: "mekanismgenerators:reactor_glass", redstone: 0b}},
        {pos: [2, 2, 4], state: "mekanismgenerators:reactor_glass", nbt: {id: "mekanismgenerators:reactor_glass", redstone: 0b}},
        {pos: [3, 2, 0], state: "mekanismgenerators:reactor_glass", nbt: {id: "mekanismgenerators:reactor_glass", redstone: 0b}},
        {pos: [3, 2, 4], state: "mekanismgenerators:reactor_glass", nbt: {id: "mekanismgenerators:reactor_glass", redstone: 0b}},
        {pos: [4, 2, 0], state: "mekanismgenerators:fusion_reactor_frame", nbt: {id: "mekanismgenerators:fusion_reactor_frame", inventory_id: [I; -838099177, -1562622799, -1910657750, 1061773453], redstone: 0b}},
        {pos: [4, 2, 1], state: "mekanismgenerators:fusion_reactor_port{active:false}", nbt: {active_state: 0b, id: "mekanismgenerators:fusion_reactor_port", inventory_id: [I; -838099177, -1562622799, -1910657750, 1061773453], redstone: 0b, update_delay: 0}},
        {pos: [4, 2, 2], state: "mekanismgenerators:laser_focus_matrix", nbt: {id: "mekanismgenerators:laser_focus_matrix", inventory_id: [I; -838099177, -1562622799, -1910657750, 1061773453], redstone: 0b}},
        {pos: [4, 2, 3], state: "mekanismgenerators:fusion_reactor_port{active:false}", nbt: {active_state: 0b, id: "mekanismgenerators:fusion_reactor_port", inventory_id: [I; -838099177, -1562622799, -1910657750, 1061773453], redstone: 0b, update_delay: 0}},
        {pos: [4, 2, 4], state: "mekanismgenerators:fusion_reactor_frame", nbt: {id: "mekanismgenerators:fusion_reactor_frame", inventory_id: [I; -838099177, -1562622799, -1910657750, 1061773453], redstone: 0b}},
        {pos: [0, 3, 1], state: "mekanismgenerators:fusion_reactor_frame", nbt: {id: "mekanismgenerators:fusion_reactor_frame", inventory_id: [I; -838099177, -1562622799, -1910657750, 1061773453], redstone: 0b}},
        {pos: [0, 3, 2], state: "mekanismgenerators:reactor_glass", nbt: {id: "mekanismgenerators:reactor_glass", redstone: 0b}},
        {pos: [0, 3, 3], state: "mekanismgenerators:fusion_reactor_frame", nbt: {id: "mekanismgenerators:fusion_reactor_frame", inventory_id: [I; -838099177, -1562622799, -1910657750, 1061773453], redstone: 0b}},
        {pos: [1, 3, 0], state: "mekanismgenerators:fusion_reactor_frame", nbt: {id: "mekanismgenerators:fusion_reactor_frame", inventory_id: [I; -838099177, -1562622799, -1910657750, 1061773453], redstone: 0b}},
        {pos: [1, 3, 4], state: "mekanismgenerators:fusion_reactor_frame", nbt: {id: "mekanismgenerators:fusion_reactor_frame", inventory_id: [I; -838099177, -1562622799, -1910657750, 1061773453], redstone: 0b}},
        {pos: [2, 3, 0], state: "mekanismgenerators:reactor_glass", nbt: {id: "mekanismgenerators:reactor_glass", redstone: 0b}},
        {pos: [2, 3, 4], state: "mekanismgenerators:reactor_glass", nbt: {id: "mekanismgenerators:reactor_glass", redstone: 0b}},
        {pos: [3, 3, 0], state: "mekanismgenerators:fusion_reactor_frame", nbt: {id: "mekanismgenerators:fusion_reactor_frame", inventory_id: [I; -838099177, -1562622799, -1910657750, 1061773453], redstone: 0b}},
        {pos: [3, 3, 4], state: "mekanismgenerators:fusion_reactor_frame", nbt: {id: "mekanismgenerators:fusion_reactor_frame", inventory_id: [I; -838099177, -1562622799, -1910657750, 1061773453], redstone: 0b}},
        {pos: [4, 3, 1], state: "mekanismgenerators:fusion_reactor_frame", nbt: {id: "mekanismgenerators:fusion_reactor_frame", inventory_id: [I; -838099177, -1562622799, -1910657750, 1061773453], redstone: 0b}},
        {pos: [4, 3, 2], state: "mekanismgenerators:reactor_glass", nbt: {id: "mekanismgenerators:reactor_glass", redstone: 0b}},
        {pos: [4, 3, 3], state: "mekanismgenerators:fusion_reactor_frame", nbt: {id: "mekanismgenerators:fusion_reactor_frame", inventory_id: [I; -838099177, -1562622799, -1910657750, 1061773453], redstone: 0b}},
        {pos: [0, 4, 2], state: "mekanismgenerators:fusion_reactor_frame", nbt: {id: "mekanismgenerators:fusion_reactor_frame", inventory_id: [I; -838099177, -1562622799, -1910657750, 1061773453], redstone: 0b}},
        {pos: [1, 4, 1], state: "mekanismgenerators:fusion_reactor_frame", nbt: {id: "mekanismgenerators:fusion_reactor_frame", inventory_id: [I; -838099177, -1562622799, -1910657750, 1061773453], redstone: 0b}},
        {pos: [1, 4, 2], state: "mekanismgenerators:fusion_reactor_frame", nbt: {id: "mekanismgenerators:fusion_reactor_frame", inventory_id: [I; -838099177, -1562622799, -1910657750, 1061773453], redstone: 0b}},
        {pos: [1, 4, 3], state: "mekanismgenerators:fusion_reactor_frame", nbt: {id: "mekanismgenerators:fusion_reactor_frame", inventory_id: [I; -838099177, -1562622799, -1910657750, 1061773453], redstone: 0b}},
        {pos: [2, 4, 0], state: "mekanismgenerators:fusion_reactor_frame", nbt: {id: "mekanismgenerators:fusion_reactor_frame", inventory_id: [I; -838099177, -1562622799, -1910657750, 1061773453], redstone: 0b}},
        {pos: [2, 4, 1], state: "mekanismgenerators:fusion_reactor_frame", nbt: {id: "mekanismgenerators:fusion_reactor_frame", inventory_id: [I; -838099177, -1562622799, -1910657750, 1061773453], redstone: 0b}},
        {pos: [2, 4, 2], state: "mekanismgenerators:fusion_reactor_controller{active:true}", nbt: {active_state: 1b, id: "mekanismgenerators:fusion_reactor_controller", inventory_id: [I; -838099177, -1562622799, -1910657750, 1061773453], redstone: 0b, update_delay: 0}},
        {pos: [2, 4, 3], state: "mekanismgenerators:fusion_reactor_frame", nbt: {id: "mekanismgenerators:fusion_reactor_frame", inventory_id: [I; -838099177, -1562622799, -1910657750, 1061773453], redstone: 0b}},
        {pos: [2, 4, 4], state: "mekanismgenerators:fusion_reactor_frame", nbt: {id: "mekanismgenerators:fusion_reactor_frame", inventory_id: [I; -838099177, -1562622799, -1910657750, 1061773453], redstone: 0b}},
        {pos: [3, 4, 1], state: "mekanismgenerators:fusion_reactor_frame", nbt: {id: "mekanismgenerators:fusion_reactor_frame", inventory_id: [I; -838099177, -1562622799, -1910657750, 1061773453], redstone: 0b}},
        {pos: [3, 4, 2], state: "mekanismgenerators:fusion_reactor_frame", nbt: {id: "mekanismgenerators:fusion_reactor_frame", inventory_id: [I; -838099177, -1562622799, -1910657750, 1061773453], redstone: 0b}},
        {pos: [3, 4, 3], state: "mekanismgenerators:fusion_reactor_frame", nbt: {id: "mekanismgenerators:fusion_reactor_frame", inventory_id: [I; -838099177, -1562622799, -1910657750, 1061773453], redstone: 0b}},
        {pos: [4, 4, 2], state: "mekanismgenerators:fusion_reactor_frame", nbt: {id: "mekanismgenerators:fusion_reactor_frame", inventory_id: [I; -838099177, -1562622799, -1910657750, 1061773453], redstone: 0b}}
    ],
    entities: [],
    palette: [
        "mekanismgenerators:fusion_reactor_frame",
        "mekanismgenerators:reactor_glass",
        "mekanismgenerators:fusion_reactor_port{active:false}",
        "mekanismgenerators:laser_focus_matrix",
        "mekanismgenerators:fusion_reactor_controller{active:true}"
    ]
}